[2025-02-09 15:31:39 +0000] [260720] [ERROR] Exception in worker process
Traceback (most recent call last):
  File "/home/aiagent/aiagent/.venv/lib/python3.12/site-packages/gunicorn/arbiter.py", line 608, in spawn_worker
    worker.init_process()
  File "/home/aiagent/aiagent/.venv/lib/python3.12/site-packages/uvicorn/workers.py", line 75, in init_process
    super().init_process()
  File "/home/aiagent/aiagent/.venv/lib/python3.12/site-packages/gunicorn/workers/base.py", line 135, in init_process
    self.load_wsgi()
  File "/home/aiagent/aiagent/.venv/lib/python3.12/site-packages/gunicorn/workers/base.py", line 147, in load_wsgi
    self.wsgi = self.app.wsgi()
                ^^^^^^^^^^^^^^^
  File "/home/aiagent/aiagent/.venv/lib/python3.12/site-packages/gunicorn/app/base.py", line 66, in wsgi
    self.callable = self.load()
                    ^^^^^^^^^^^
  File "/home/aiagent/aiagent/.venv/lib/python3.12/site-packages/gunicorn/app/wsgiapp.py", line 57, in load
    return self.load_wsgiapp()
           ^^^^^^^^^^^^^^^^^^^
  File "/home/aiagent/aiagent/.venv/lib/python3.12/site-packages/gunicorn/app/wsgiapp.py", line 47, in load_wsgiapp
    return util.import_app(self.app_uri)
           ^^^^^^^^^^^^^^^^^^^^^^^^^^^^^
  File "/home/aiagent/aiagent/.venv/lib/python3.12/site-packages/gunicorn/util.py", line 370, in import_app
    mod = importlib.import_module(module)
          ^^^^^^^^^^^^^^^^^^^^^^^^^^^^^^^
  File "/usr/lib/python3.12/importlib/__init__.py", line 90, in import_module
    return _bootstrap._gcd_import(name[level:], package, level)
           ^^^^^^^^^^^^^^^^^^^^^^^^^^^^^^^^^^^^^^^^^^^^^^^^^^^^
  File "<frozen importlib._bootstrap>", line 1387, in _gcd_import
  File "<frozen importlib._bootstrap>", line 1360, in _find_and_load
  File "<frozen importlib._bootstrap>", line 1324, in _find_and_load_unlocked
ModuleNotFoundError: No module named 'main'
[2025-02-09 15:31:39 +0000] [260721] [ERROR] Exception in worker process
Traceback (most recent call last):
  File "/home/aiagent/aiagent/.venv/lib/python3.12/site-packages/gunicorn/arbiter.py", line 608, in spawn_worker
    worker.init_process()
  File "/home/aiagent/aiagent/.venv/lib/python3.12/site-packages/uvicorn/workers.py", line 75, in init_process
    super().init_process()
  File "/home/aiagent/aiagent/.venv/lib/python3.12/site-packages/gunicorn/workers/base.py", line 135, in init_process
    self.load_wsgi()
  File "/home/aiagent/aiagent/.venv/lib/python3.12/site-packages/gunicorn/workers/base.py", line 147, in load_wsgi
    self.wsgi = self.app.wsgi()
                ^^^^^^^^^^^^^^^
  File "/home/aiagent/aiagent/.venv/lib/python3.12/site-packages/gunicorn/app/base.py", line 66, in wsgi
    self.callable = self.load()
                    ^^^^^^^^^^^
  File "/home/aiagent/aiagent/.venv/lib/python3.12/site-packages/gunicorn/app/wsgiapp.py", line 57, in load
    return self.load_wsgiapp()
           ^^^^^^^^^^^^^^^^^^^
  File "/home/aiagent/aiagent/.venv/lib/python3.12/site-packages/gunicorn/app/wsgiapp.py", line 47, in load_wsgiapp
    return util.import_app(self.app_uri)
           ^^^^^^^^^^^^^^^^^^^^^^^^^^^^^
  File "/home/aiagent/aiagent/.venv/lib/python3.12/site-packages/gunicorn/util.py", line 370, in import_app
    mod = importlib.import_module(module)
          ^^^^^^^^^^^^^^^^^^^^^^^^^^^^^^^
  File "/usr/lib/python3.12/importlib/__init__.py", line 90, in import_module
    return _bootstrap._gcd_import(name[level:], package, level)
           ^^^^^^^^^^^^^^^^^^^^^^^^^^^^^^^^^^^^^^^^^^^^^^^^^^^^
  File "<frozen importlib._bootstrap>", line 1387, in _gcd_import
  File "<frozen importlib._bootstrap>", line 1360, in _find_and_load
  File "<frozen importlib._bootstrap>", line 1324, in _find_and_load_unlocked
ModuleNotFoundError: No module named 'main'
[2025-02-09 15:31:39 +0000] [260719] [ERROR] Worker (pid:260720) exited with code 3
[2025-02-09 15:31:39 +0000] [260719] [ERROR] Worker (pid:260721) was sent SIGTERM!
[2025-02-09 15:31:39 +0000] [260719] [ERROR] Shutting down: Master
[2025-02-09 15:31:39 +0000] [260719] [ERROR] Reason: Worker failed to boot.
[2025-02-09 15:31:40 +0000] [260762] [ERROR] Exception in worker process
Traceback (most recent call last):
  File "/home/aiagent/aiagent/.venv/lib/python3.12/site-packages/gunicorn/arbiter.py", line 608, in spawn_worker
    worker.init_process()
  File "/home/aiagent/aiagent/.venv/lib/python3.12/site-packages/uvicorn/workers.py", line 75, in init_process
    super().init_process()
  File "/home/aiagent/aiagent/.venv/lib/python3.12/site-packages/gunicorn/workers/base.py", line 135, in init_process
    self.load_wsgi()
  File "/home/aiagent/aiagent/.venv/lib/python3.12/site-packages/gunicorn/workers/base.py", line 147, in load_wsgi
    self.wsgi = self.app.wsgi()
                ^^^^^^^^^^^^^^^
  File "/home/aiagent/aiagent/.venv/lib/python3.12/site-packages/gunicorn/app/base.py", line 66, in wsgi
    self.callable = self.load()
                    ^^^^^^^^^^^
  File "/home/aiagent/aiagent/.venv/lib/python3.12/site-packages/gunicorn/app/wsgiapp.py", line 57, in load
    return self.load_wsgiapp()
           ^^^^^^^^^^^^^^^^^^^
  File "/home/aiagent/aiagent/.venv/lib/python3.12/site-packages/gunicorn/app/wsgiapp.py", line 47, in load_wsgiapp
    return util.import_app(self.app_uri)
           ^^^^^^^^^^^^^^^^^^^^^^^^^^^^^
  File "/home/aiagent/aiagent/.venv/lib/python3.12/site-packages/gunicorn/util.py", line 370, in import_app
    mod = importlib.import_module(module)
          ^^^^^^^^^^^^^^^^^^^^^^^^^^^^^^^
  File "/usr/lib/python3.12/importlib/__init__.py", line 90, in import_module
    return _bootstrap._gcd_import(name[level:], package, level)
           ^^^^^^^^^^^^^^^^^^^^^^^^^^^^^^^^^^^^^^^^^^^^^^^^^^^^
  File "<frozen importlib._bootstrap>", line 1387, in _gcd_import
  File "<frozen importlib._bootstrap>", line 1360, in _find_and_load
  File "<frozen importlib._bootstrap>", line 1324, in _find_and_load_unlocked
ModuleNotFoundError: No module named 'main'
[2025-02-09 15:31:40 +0000] [260761] [ERROR] Worker (pid:260762) exited with code 3
[2025-02-09 15:31:40 +0000] [260761] [ERROR] Shutting down: Master
[2025-02-09 15:31:40 +0000] [260761] [ERROR] Reason: Worker failed to boot.
[2025-02-09 15:31:42 +0000] [260783] [ERROR] Exception in worker process
Traceback (most recent call last):
  File "/home/aiagent/aiagent/.venv/lib/python3.12/site-packages/gunicorn/arbiter.py", line 608, in spawn_worker
    worker.init_process()
  File "/home/aiagent/aiagent/.venv/lib/python3.12/site-packages/uvicorn/workers.py", line 75, in init_process
    super().init_process()
  File "/home/aiagent/aiagent/.venv/lib/python3.12/site-packages/gunicorn/workers/base.py", line 135, in init_process
    self.load_wsgi()
  File "/home/aiagent/aiagent/.venv/lib/python3.12/site-packages/gunicorn/workers/base.py", line 147, in load_wsgi
    self.wsgi = self.app.wsgi()
                ^^^^^^^^^^^^^^^
  File "/home/aiagent/aiagent/.venv/lib/python3.12/site-packages/gunicorn/app/base.py", line 66, in wsgi
    self.callable = self.load()
                    ^^^^^^^^^^^
  File "/home/aiagent/aiagent/.venv/lib/python3.12/site-packages/gunicorn/app/wsgiapp.py", line 57, in load
    return self.load_wsgiapp()
           ^^^^^^^^^^^^^^^^^^^
  File "/home/aiagent/aiagent/.venv/lib/python3.12/site-packages/gunicorn/app/wsgiapp.py", line 47, in load_wsgiapp
    return util.import_app(self.app_uri)
           ^^^^^^^^^^^^^^^^^^^^^^^^^^^^^
  File "/home/aiagent/aiagent/.venv/lib/python3.12/site-packages/gunicorn/util.py", line 370, in import_app
    mod = importlib.import_module(module)
          ^^^^^^^^^^^^^^^^^^^^^^^^^^^^^^^
  File "/usr/lib/python3.12/importlib/__init__.py", line 90, in import_module
    return _bootstrap._gcd_import(name[level:], package, level)
           ^^^^^^^^^^^^^^^^^^^^^^^^^^^^^^^^^^^^^^^^^^^^^^^^^^^^
  File "<frozen importlib._bootstrap>", line 1387, in _gcd_import
  File "<frozen importlib._bootstrap>", line 1360, in _find_and_load
  File "<frozen importlib._bootstrap>", line 1324, in _find_and_load_unlocked
ModuleNotFoundError: No module named 'main'
[2025-02-09 15:31:42 +0000] [260782] [ERROR] Worker (pid:260783) exited with code 3
[2025-02-09 15:31:42 +0000] [260782] [ERROR] Shutting down: Master
[2025-02-09 15:31:42 +0000] [260782] [ERROR] Reason: Worker failed to boot.
[2025-02-09 15:31:45 +0000] [260822] [ERROR] Exception in worker process
Traceback (most recent call last):
  File "/home/aiagent/aiagent/.venv/lib/python3.12/site-packages/gunicorn/arbiter.py", line 608, in spawn_worker
    worker.init_process()
  File "/home/aiagent/aiagent/.venv/lib/python3.12/site-packages/uvicorn/workers.py", line 75, in init_process
    super().init_process()
  File "/home/aiagent/aiagent/.venv/lib/python3.12/site-packages/gunicorn/workers/base.py", line 135, in init_process
    self.load_wsgi()
  File "/home/aiagent/aiagent/.venv/lib/python3.12/site-packages/gunicorn/workers/base.py", line 147, in load_wsgi
    self.wsgi = self.app.wsgi()
                ^^^^^^^^^^^^^^^
  File "/home/aiagent/aiagent/.venv/lib/python3.12/site-packages/gunicorn/app/base.py", line 66, in wsgi
    self.callable = self.load()
                    ^^^^^^^^^^^
  File "/home/aiagent/aiagent/.venv/lib/python3.12/site-packages/gunicorn/app/wsgiapp.py", line 57, in load
    return self.load_wsgiapp()
           ^^^^^^^^^^^^^^^^^^^
  File "/home/aiagent/aiagent/.venv/lib/python3.12/site-packages/gunicorn/app/wsgiapp.py", line 47, in load_wsgiapp
    return util.import_app(self.app_uri)
           ^^^^^^^^^^^^^^^^^^^^^^^^^^^^^
  File "/home/aiagent/aiagent/.venv/lib/python3.12/site-packages/gunicorn/util.py", line 370, in import_app
    mod = importlib.import_module(module)
          ^^^^^^^^^^^^^^^^^^^^^^^^^^^^^^^
  File "/usr/lib/python3.12/importlib/__init__.py", line 90, in import_module
    return _bootstrap._gcd_import(name[level:], package, level)
           ^^^^^^^^^^^^^^^^^^^^^^^^^^^^^^^^^^^^^^^^^^^^^^^^^^^^
  File "<frozen importlib._bootstrap>", line 1387, in _gcd_import
  File "<frozen importlib._bootstrap>", line 1360, in _find_and_load
  File "<frozen importlib._bootstrap>", line 1324, in _find_and_load_unlocked
ModuleNotFoundError: No module named 'main'
[2025-02-09 15:31:45 +0000] [260821] [ERROR] Worker (pid:260822) exited with code 3
[2025-02-09 15:31:45 +0000] [260821] [ERROR] Shutting down: Master
[2025-02-09 15:31:45 +0000] [260821] [ERROR] Reason: Worker failed to boot.
[2025-02-09 15:35:53 +0000] [263598] [ERROR] Worker (pid:263601) was sent SIGTERM!
[2025-02-09 15:35:53 +0000] [263598] [ERROR] Worker (pid:263600) was sent SIGTERM!
[2025-02-09 15:35:53 +0000] [263598] [ERROR] Worker (pid:263599) was sent SIGTERM!
